Workbook

Sheet Bldg C 12WLOA
A1: # | B1: MEETING AGENDA
A2: A | B2: MEETING DETAILS
B3: MEETING. | E3: PRODUCTION
B4: WEEK NO. | E4: =WEEKNUM(E6) -> 9
B5: SECTION | E5: C
B6: DATE | E6: 46078
B7: TIME | E7: 0.4375
B8: LOCATION | E8: Building C : R005
B9: PURPOSE | E9: - To support and protect the Production Plan - To strive for improved Production Plan stability and predictability.
B10: NEXT MEETING | E10: =E6+7 -> 46085
A12: B | B12: STAKEHOLDERS | C12: Org. | D12: In Attendance | E12: Name | F12: Column1
B13: =IF(ISBLANK(E13), "", INDEX(OWNER_LIST[Role], MATCH(E13,OWNER_LIST[Owner Name], 0))) -> Project Manager (PM) | C13: =IF(ISBLANK(E13), "", INDEX(OWNER_LIST[Owner ORG], MATCH(E13,OWNER_LIST[Owner Name], 0))) -> RPN | D13: Yes | E13: Lorenzo Barnini
B14: =IF(ISBLANK(E14), "", INDEX(OWNER_LIST[Role], MATCH(E14,OWNER_LIST[Owner Name], 0))) -> Construction Manager | C14: =IF(ISBLANK(E14), "", INDEX(OWNER_LIST[Owner ORG], MATCH(E14,OWNER_LIST[Owner Name], 0))) -> RPN | D14: Yes | E14: Matteo Naldi
B15: =IF(ISBLANK(E15), "", INDEX(OWNER_LIST[Role], MATCH(E15,OWNER_LIST[Owner Name], 0))) -> Cost Control Manager | C15: =IF(ISBLANK(E15), "", INDEX(OWNER_LIST[Owner ORG], MATCH(E15,OWNER_LIST[Owner Name], 0))) -> RPN | D15: No | E15: Jessica Donatelli
B16: =IF(ISBLANK(E16), "", INDEX(OWNER_LIST[Role], MATCH(E16,OWNER_LIST[Owner Name], 0))) -> Engineering Chief & Move Manager | C16: =IF(ISBLANK(E16), "", INDEX(OWNER_LIST[Owner ORG], MATCH(E16,OWNER_LIST[Owner Name], 0))) -> RPN | D16: Yes | E16: Federica Brunone
B17: =IF(ISBLANK(E17), "", INDEX(OWNER_LIST[Role], MATCH(E17,OWNER_LIST[Owner Name], 0))) -> Arch Design Specialist | C17: =IF(ISBLANK(E17), "", INDEX(OWNER_LIST[Owner ORG], MATCH(E17,OWNER_LIST[Owner Name], 0))) -> RPN | D17: No | E17: Chiara Re Depaolini
B18: =IF(ISBLANK(E18), "", INDEX(OWNER_LIST[Role], MATCH(E18,OWNER_LIST[Owner Name], 0))) -> Schedule Manager | C18: =IF(ISBLANK(E18), "", INDEX(OWNER_LIST[Owner ORG], MATCH(E18,OWNER_LIST[Owner Name], 0))) -> RPN | D18: Yes | E18: Simone Conti
B19: =IF(ISBLANK(E19), "", INDEX(OWNER_LIST[Role], MATCH(E19,OWNER_LIST[Owner Name], 0))) -> Move Specialist / Doc Controller | C19: =IF(ISBLANK(E19), "", INDEX(OWNER_LIST[Owner ORG], MATCH(E19,OWNER_LIST[Owner Name], 0))) -> RPN | D19: No | E19: Martina Maffioletti
B20: =IF(ISBLANK(E20), "", INDEX(OWNER_LIST[Role], MATCH(E20,OWNER_LIST[Owner Name], 0))) -> Electrical Engineer | C20: =IF(ISBLANK(E20), "", INDEX(OWNER_LIST[Owner ORG], MATCH(E20,OWNER_LIST[Owner Name], 0))) -> RPN | D20: Yes | E20: Hacir Degirmencioglu
B21: =IF(ISBLANK(E21), "", INDEX(OWNER_LIST[Role], MATCH(E21,OWNER_LIST[Owner Name], 0))) -> Deputy Quality Manager | C21: =IF(ISBLANK(E21), "", INDEX(OWNER_LIST[Owner ORG], MATCH(E21,OWNER_LIST[Owner Name], 0))) -> RPN | D21: Yes | E21: Leonardo Valentinotti
B22: =IF(ISBLANK(E22), "", INDEX(OWNER_LIST[Role], MATCH(E22,OWNER_LIST[Owner Name], 0))) -> HSE & Security Manager | C22: =IF(ISBLANK(E22), "", INDEX(OWNER_LIST[Owner ORG], MATCH(E22,OWNER_LIST[Owner Name], 0))) -> RPN | D22: Yes | E22: MariaCristina Menozzi
B23: =IF(ISBLANK(E23), "", INDEX(OWNER_LIST[Role], MATCH(E23,OWNER_LIST[Owner Name], 0))) -> Architectural Manager | C23: =IF(ISBLANK(E23), "", INDEX(OWNER_LIST[Owner ORG], MATCH(E23,OWNER_LIST[Owner Name], 0))) -> SHP | D23: Yes | E23: Zeynep Onen
B24: =IF(ISBLANK(E24), "", INDEX(OWNER_LIST[Role], MATCH(E24,OWNER_LIST[Owner Name], 0))) -> Chief Design and Construction | C24: =IF(ISBLANK(E24), "", INDEX(OWNER_LIST[Owner ORG], MATCH(E24,OWNER_LIST[Owner Name], 0))) -> SHP | D24: Yes | E24: Neil Bradley
... B35: =IF(ISBLANK(E35), "", INDEX(OWNER_LIST[Role], MATCH(E35,OWNER_LIST[Owner Name], 0))) -> Quality Manager | C35: =IF(ISBLANK(E35), "", INDEX(OWNER_LIST[Owner ORG], MATCH(E35,OWNER_LIST[Owner Name], 0))) -> SHP | D35: Yes | E35: Didier Dequatre
A37: C1 | B37: MEETING TOPIC | C37: ACTION - INFO | D37: STATUS | E37: DESCRIPTION - INFORMATION LOG | F37: ACTION REQUIRED | G37: PRIORITY | H37: DUE DATE | I37: OWNER ORG. | J37: OWNER NAME 1 | K37: OWNER NAME 2 | L37: DISCIPLINE | M37: DATE LOGGED | N37: DATE CLOSED | O37: ESCALATE | P37: Note | Q37: Row_PM | R37: Notify_PM | S37: Condition_PM | T37: ROW | U37: Email_Name_1 | V37: Email_Name_2 | W37: SECTION | X37: Nonull
A38: C_1 | B38: HEALTH & SAFETY | X38: =IF( OR( AND( NOT(ISBLANK(C_1[[#This Row],[DESCRIPTION - INFORMATION LOG]])), C_1[[#This Row],[DESCRIPTION - INFORMATION LOG]] <> "DESCRIPTION - INFORMATION LOG" ), NOT(ISBLANK(C_1[[#This Row],[ACTION REQUIRED]])) ), "Y", "N" ) -> N
A39: HSE | B39: Fire closure between Bldg C and AC - Level 4 & 5 | D39: CLOSED | E39: Permenent FR glazed door instaled at level 4 and 5 are not closing properly | F39: 07.01: RPN to repair the locks. | G39: TOP | H39: 46050 | I39: {=IFERROR(_xlfn.TEXTJOIN(" / ", TRUE, IF(OWNER_LIST[Owner Name]=C_1[[#This Row],[OWNER NAME 1]], OWNER_LIST[Owner ORG], ""), IF(OWNER_LIST[Owner Name]=C_1[[#This Row],[OWNER NAME 2]], OWNER_LIST[Owner ORG], "")), "")} -> RPN | J39: Matteo Naldi | R39: =_xlfn.CONCAT(C_1[[#This Row],[ESCALATE]], "-",C_1[[#This Row],[Row_PM]]) -> - | S39: =_xlfn.CONCAT(C_1[[#This Row],[ESCALATE]], "-",C_1[[#This Row],[Notify_PM]]) -> -- | T39: =ROW() -> 39 | U39: =IF(C_1[[#This Row],[OWNER NAME 1]] = "", "", IF(_xlfn.XLOOKUP(C_1[[#This Row],[OWNER NAME 1]],OWNER_LIST[Owner Name], OWNER_LIST[Email], "") = "", "", _xlfn.XLOOKUP(C_1[[#This Row],[OWNER NAME 1]], OWNER_LIST[Owner Name], OWNER_LIST[Email], ""))) -> matteo.naldi@cmbcarpi.it | V39: =IF(C_1[[#This Row],[OWNER NAME 2]] = "", "", IF(_xlfn.XLOOKUP(C_1[[#This Row],[OWNER NAME 2]],OWNER_LIST[Owner Name], OWNER_LIST[Email], "") = "", "", _xlfn.XLOOKUP(C_1[[#This Row],[OWNER NAME 2]], OWNER_LIST[Owner Name], OWNER_LIST[Email], ""))) | W39: =$A$37 -> C1 | X39: =IF( OR( AND( NOT(ISBLANK(C_1[[#This Row],[DESCRIPTION - INFORMATION LOG]])), C_1[[#This Row],[DESCRIPTION - INFORMATION LOG]] <> "DESCRIPTION - INFORMATION LOG" ), NOT(ISBLANK(C_1[[#This Row],[ACTION REQUIRED]])) ), "Y", "N" ) -> Y
I40: {=IFERROR(_xlfn.TEXTJOIN(" / ", TRUE, IF(OWNER_LIST[Owner Name]=C_1[[#This Row],[OWNER NAME 1]], OWNER_LIST[Owner ORG], ""), IF(OWNER_LIST[Owner Name]=C_1[[#This Row],[OWNER NAME 2]], OWNER_LIST[Owner ORG], "")), "")} | R40: =_xlfn.CONCAT(C_1[[#This Row],[ESCALATE]], "-",C_1[[#This Row],[Row_PM]]) -> - | S40: =_xlfn.CONCAT(C_1[[#This Row],[ESCALATE]], "-",C_1[[#This Row],[Notify_PM]]) -> -- | T40: =ROW() -> 40 | U40: =IF(C_1[[#This Row],[OWNER NAME 1]] = "", "", IF(_xlfn.XLOOKUP(C_1[[#This Row],[OWNER NAME 1]],OWNER_LIST[Owner Name], OWNER_LIST[Email], "") = "", "", _xlfn.XLOOKUP(C_1[[#This Row],[OWNER NAME 1]], OWNER_LIST[Owner Name], OWNER_LIST[Email], ""))) | V40: =IF(C_1[[#This Row],[OWNER NAME 2]] = "", "", IF(_xlfn.XLOOKUP(C_1[[#This Row],[OWNER NAME 2]],OWNER_LIST[Owner Name], OWNER_LIST[Email], "") = "", "", _xlfn.XLOOKUP(C_1[[#This Row],[OWNER NAME 2]], OWNER_LIST[Owner Name], OWNER_LIST[Email], ""))) | W40: =$A$37 -> C1 | X40: =IF( OR( AND( NOT(ISBLANK(C_1[[#This Row],[DESCRIPTION - INFORMATION LOG]])), C_1[[#This Row],[DESCRIPTION - INFORMATION LOG]] <> "DESCRIPTION - INFORMATION LOG" ), NOT(ISBLANK(C_1[[#This Row],[ACTION REQUIRED]])) ), "Y", "N" ) -> N
A41: C_2 | B41: PRODUCTION | X41: =IF( OR( AND( NOT(ISBLANK(C_1[[#This Row],[DESCRIPTION - INFORMATION LOG]])), C_1[[#This Row],[DESCRIPTION - INFORMATION LOG]] <> "DESCRIPTION - INFORMATION LOG" ), NOT(ISBLANK(C_1[[#This Row],[ACTION REQUIRED]])) ), "Y", "N" ) -> N
A42: GENERAL | B42: SUBSTANTIAL COMPLETION | C42: INFO | D42: OPEN | E42: 18.02: Substantial completion is pending availability of EGGTELSA manpower on site 04.03 | F42: 25.02: Official S.C. 24.04 (no exclusion) 04.03: RPN to confirm which areas can be delivered on 24.04. | G42: High | H42: 46087 | I42: {=IFERROR(_xlfn.TEXTJOIN(" / ", TRUE, IF(OWNER_LIST[Owner Name]=C_1[[#This Row],[OWNER NAME 1]], OWNER_LIST[Owner ORG], ""), IF(OWNER_LIST[Owner Name]=C_1[[#This Row],[OWNER NAME 2]], OWNER_LIST[Owner ORG], "")), "")} -> RPN | J42: Simone Conti | R42: =_xlfn.CONCAT(C_1[[#This Row],[ESCALATE]], "-",C_1[[#This Row],[Row_PM]]) -> - | S42: =_xlfn.CONCAT(C_1[[#This Row],[ESCALATE]], "-",C_1[[#This Row],[Notify_PM]]) -> -- | T42: =ROW() -> 42 | U42: =IF(C_1[[#This Row],[OWNER NAME 1]] = "", "", IF(_xlfn.XLOOKUP(C_1[[#This Row],[OWNER NAME 1]],OWNER_LIST[Owner Name], OWNER_LIST[Email], "") = "", "", _xlfn.XLOOKUP(C_1[[#This Row],[OWNER NAME 1]], OWNER_LIST[Owner Name], OWNER_LIST[Email], ""))) -> simone.conti@cmbcarpi.it | V42: =IF(C_1[[#This Row],[OWNER NAME 2]] = "", "", IF(_xlfn.XLOOKUP(C_1[[#This Row],[OWNER NAME 2]],OWNER_LIST[Owner Name], OWNER_LIST[Email], "") = "", "", _xlfn.XLOOKUP(C_1[[#This Row],[OWNER NAME 2]], OWNER_LIST[Owner Name], OWNER_LIST[Email], ""))) | W42: =$A$37 -> C1 | X42: =IF( OR( AND( NOT(ISBLANK(C_1[[#This Row],[DESCRIPTION - INFORMATION LOG]])), C_1[[#This Row],[DESCRIPTION - INFORMATION LOG]] <> "DESCRIPTION - INFORMATION LOG" ), NOT(ISBLANK(C_1[[#This Row],[ACTION REQUIRED]])) ), "Y", "N" ) -> Y
A43: GENERAL | B43: SUBSTANTIAL COMPLETION | C43: INFO | D43: OPEN | E43: 07.05: Program have been updated with new S.C 16.12 TIA to 16.12 due to VAR 576 C6 / PRESS BAR / COUNCIL CHAMBER - NCF 334 salle C6 (see details bellow) - NCF 367 fire enclosure (see details bellow) | F43: 14.05: Complete the works by the end of July 05.11: RPN to update board | G43: High | I43: {=IFERROR(_xlfn.TEXTJOIN(" / ", TRUE, IF(OWNER_LIST[Owner Name]=C_1[[#This Row],[OWNER NAME 1]], OWNER_LIST[Owner ORG], ""), IF(OWNER_LIST[Owner Name]=C_1[[#This Row],[OWNER NAME 2]], OWNER_LIST[Owner ORG], "")), "")} | R43: =_xlfn.CONCAT(C_1[[#This Row],[ESCALATE]], "-",C_1[[#This Row],[Row_PM]]) -> - | S43: =_xlfn.CONCAT(C_1[[#This Row],[ESCALATE]], "-",C_1[[#This Row],[Notify_PM]]) -> -- | T43: =ROW() -> 43 | U43: =IF(C_1[[#This Row],[OWNER NAME 1]] = "", "", IF(_xlfn.XLOOKUP(C_1[[#This Row],[OWNER NAME 1]],OWNER_LIST[Owner Name], OWNER_LIST[Email], "") = "", "", _xlfn.XLOOKUP(C_1[[#This Row],[OWNER NAME 1]], OWNER_LIST[Owner Name], OWNER_LIST[Email], ""))) | V43: =IF(C_1[[#This Row],[OWNER NAME 2]] = "", "", IF(_xlfn.XLOOKUP(C_1[[#This Row],[OWNER NAME 2]],OWNER_LIST[Owner Name], OWNER_LIST[Email], "") = "", "", _xlfn.XLOOKUP(C_1[[#This Row],[OWNER NAME 2]], OWNER_LIST[Owner Name], OWNER_LIST[Email], ""))) | W43: =$A$37 -> C1 | X43: =IF( OR( AND( NOT(ISBLANK(C_1[[#This Row],[DESCRIPTION - INFORMATION LOG]])), C_1[[#This Row],[DESCRIPTION - INFORMATION LOG]] <> "DESCRIPTION - INFORMATION LOG" ), NOT(ISBLANK(C_1[[#This Row],[ACTION REQUIRED]])) ), "Y", "N" ) -> Y
A44: GENERAL | B44: PPC | C44: INFO | D44: OPEN | E44: 0.6 | F44: 22.10: Blocking topic: - Lack of resources (EGGTELSA LB2/ Council chamber) - EGGTELSA have 25# on site (C + B + S2) - 8 to 10 peoples missing - Electrical instalation at LB2 - EGL | G44: Low | I44: {=IFERROR(_xlfn.TEXTJOIN(" / ", TRUE, IF(OWNER_LIST[Owner Name]=C_1[[#This Row],[OWNER NAME 1]], OWNER_LIST[Owner ORG], ""), IF(OWNER_LIST[Owner Name]=C_1[[#This Row],[OWNER NAME 2]], OWNER_LIST[Owner ORG], "")), "")} | R44: =_xlfn.CONCAT(C_1[[#This Row],[ESCALATE]], "-",C_1[[#This Row],[Row_PM]]) -> - | S44: =_xlfn.CONCAT(C_1[[#This Row],[ESCALATE]], "-",C_1[[#This Row],[Notify_PM]]) -> -- | T44: =ROW() -> 44 | U44: =IF(C_1[[#This Row],[OWNER NAME 1]] = "", "", IF(_xlfn.XLOOKUP(C_1[[#This Row],[OWNER NAME 1]],OWNER_LIST[Owner Name], OWNER_LIST[Email], "") = "", "", _xlfn.XLOOKUP(C_1[[#This Row],[OWNER NAME 1]], OWNER_LIST[Owner Name], OWNER_LIST[Email], ""))) | V44: =IF(C_1[[#This Row],[OWNER NAME 2]] = "", "", IF(_xlfn.XLOOKUP(C_1[[#This Row],[OWNER NAME 2]],OWNER_LIST[Owner Name], OWNER_LIST[Email], "") = "", "", _xlfn.XLOOKUP(C_1[[#This Row],[OWNER NAME 2]], OWNER_LIST[Owner Name], OWNER_LIST[Email], ""))) | W44: =$A$37 -> C1 | X44: =IF( OR( AND( NOT(ISBLANK(C_1[[#This Row],[DESCRIPTION - INFORMATION LOG]])), C_1[[#This Row],[DESCRIPTION - INFORMATION LOG]] <> "DESCRIPTION - INFORMATION LOG" ), NOT(ISBLANK(C_1[[#This Row],[ACTION REQUIRED]])) ), "Y", "N" ) -> Y
A45: GENERAL | B45: POLICE DU FEU | C45: INFO | D45: OPEN | E45: 21.01: Planed 14.04 | G45: Medium | I45: {=IFERROR(_xlfn.TEXTJOIN(" / ", TRUE, IF(OWNER_LIST[Owner Name]=C_1[[#This Row],[OWNER NAME 1]], OWNER_LIST[Owner ORG], ""), IF(OWNER_LIST[Owner Name]=C_1[[#This Row],[OWNER NAME 2]], OWNER_LIST[Owner ORG], "")), "")} | R45: =_xlfn.CONCAT(C_1[[#This Row],[ESCALATE]], "-",C_1[[#This Row],[Row_PM]]) -> - | S45: =_xlfn.CONCAT(C_1[[#This Row],[ESCALATE]], "-",C_1[[#This Row],[Notify_PM]]) -> -- | T45: =ROW() -> 45 | U45: =IF(C_1[[#This Row],[OWNER NAME 1]] = "", "", IF(_xlfn.XLOOKUP(C_1[[#This Row],[OWNER NAME 1]],OWNER_LIST[Owner Name], OWNER_LIST[Email], "") = "", "", _xlfn.XLOOKUP(C_1[[#This Row],[OWNER NAME 1]], OWNER_LIST[Owner Name], OWNER_LIST[Email], ""))) | V45: =IF(C_1[[#This Row],[OWNER NAME 2]] = "", "", IF(_xlfn.XLOOKUP(C_1[[#This Row],[OWNER NAME 2]],OWNER_LIST[Owner Name], OWNER_LIST[Email], "") = "", "", _xlfn.XLOOKUP(C_1[[#This Row],[OWNER NAME 2]], OWNER_LIST[Owner Name], OWNER_LIST[Email], ""))) | W45: =$A$37 -> C1 | X45: =IF( OR( AND( NOT(ISBLANK(C_1[[#This Row],[DESCRIPTION - INFORMATION LOG]])), C_1[[#This Row],[DESCRIPTION - INFORMATION LOG]] <> "DESCRIPTION - INFORMATION LOG" ), NOT(ISBLANK(C_1[[#This Row],[ACTION REQUIRED]])) ), "Y", "N" ) -> Y
A46: GENERAL | B46: WINDOWS - NCF 382 (A-AB-C) | C46: ACTION | D46: OPEN | E46: 18.02: New quality topic has been issued concerning windows NCF 18.02: Powder coating is cracking. 24.02: NCF 382 has been raised +/- 40 windows afected. 25.02: Supplier visited site | F46: 25.02: RPN to organize site inspection with Manufacturer. +/- 03.03. | G46: TOP | H46: 46080 | I46: {=IFERROR(_xlfn.TEXTJOIN(" / ", TRUE, IF(OWNER_LIST[Owner Name]=C_1[[#This Row],[OWNER NAME 1]], OWNER_LIST[Owner ORG], ""), IF(OWNER_LIST[Owner Name]=C_1[[#This Row],[OWNER NAME 2]], OWNER_LIST[Owner ORG], "")), "")} -> RPN / SHP | J46: Davide Cirillo | K46: Didier Dequatre | R46: =_xlfn.CONCAT(C_1[[#This Row],[ESCALATE]], "-",C_1[[#This Row],[Row_PM]]) -> - | S46: =_xlfn.CONCAT(C_1[[#This Row],[ESCALATE]], "-",C_1[[#This Row],[Notify_PM]]) -> -- | T46: =ROW() -> 46 | U46: =IF(C_1[[#This Row],[OWNER NAME 1]] = "", "", IF(_xlfn.XLOOKUP(C_1[[#This Row],[OWNER NAME 1]],OWNER_LIST[Owner Name], OWNER_LIST[Email], "") = "", "", _xlfn.XLOOKUP(C_1[[#This Row],[OWNER NAME 1]], OWNER_LIST[Owner Name], OWNER_LIST[Email], ""))) -> davide.cirillo@cmbcarpi.it | V46: =IF(C_1[[#This Row],[OWNER NAME 2]] = "", "", IF(_xlfn.XLOOKUP(C_1[[#This Row],[OWNER NAME 2]],OWNER_LIST[Owner Name], OWNER_LIST[Email], "") = "", "", _xlfn.XLOOKUP(C_1[[#This Row],[OWNER NAME 2]], OWNER_LIST[Owner Name], OWNER_LIST[Email], ""))) -> didier.dequatre@un.org | W46: =$A$37 -> C1 | X46: =IF( OR( AND( NOT(ISBLANK(C_1[[#This Row],[DESCRIPTION - INFORMATION LOG]])), C_1[[#This Row],[DESCRIPTION - INFORMATION LOG]] <> "DESCRIPTION - INFORMATION LOG" ), NOT(ISBLANK(C_1[[#This Row],[ACTION REQUIRED]])) ), "Y", "N" ) -> Y
A47: DESIGN | B47: Phase 6 dwg As build dwg | C47: INFO | D47: OPEN | E47: 28.01: +/- 100 Phase 6 dwg with R&R status 16.02: As built dwg list has been submitted | F47: 04/03: SHP to assess | G47: Medium | H47: 46094 | I47: {=IFERROR(_xlfn.TEXTJOIN(" / ", TRUE, IF(OWNER_LIST[Owner Name]=C_1[[#This Row],[OWNER NAME 1]], OWNER_LIST[Owner ORG], ""), IF(OWNER_LIST[Owner Name]=C_1[[#This Row],[OWNER NAME 2]], OWNER_LIST[Owner ORG], "")), "")} -> SHP / SHP | J47: Donatella Rocca | K47: Jean-Mathieu Ferre | R47: =_xlfn.CONCAT(C_1[[#This Row],[ESCALATE]], "-",C_1[[#This Row],[Row_PM]]) -> - | S47: =_xlfn.CONCAT(C_1[[#This Row],[ESCALATE]], "-",C_1[[#This Row],[Notify_PM]]) -> -- | T47: =ROW() -> 47 | U47: =IF(C_1[[#This Row],[OWNER NAME 1]] = "", "", IF(_xlfn.XLOOKUP(C_1[[#This Row],[OWNER NAME 1]],OWNER_LIST[Owner Name], OWNER_LIST[Email], "") = "", "", _xlfn.XLOOKUP(C_1[[#This Row],[OWNER NAME 1]], OWNER_LIST[Owner Name], OWNER_LIST[Email], ""))) -> donatella.rocca@un.org | V47: =IF(C_1[[#This Row],[OWNER NAME 2]] = "", "", IF(_xlfn.XLOOKUP(C_1[[#This Row],[OWNER NAME 2]],OWNER_LIST[Owner Name], OWNER_LIST[Email], "") = "", "", _xlfn.XLOOKUP(C_1[[#This Row],[OWNER NAME 2]], OWNER_LIST[Owner Name], OWNER_LIST[Email], ""))) -> jean.ferre@un.org | W47: =$A$37 -> C1 | X47: =IF( OR( AND( NOT(ISBLANK(C_1[[#This Row],[DESCRIPTION - INFORMATION LOG]])), C_1[[#This Row],[DESCRIPTION - INFORMATION LOG]] <> "DESCRIPTION - INFORMATION LOG" ), NOT(ISBLANK(C_1[[#This Row],[ACTION REQUIRED]])) ), "Y", "N" ) -> Y
A48: GENERAL | B48: TCI - Follow-Up | C48: INFO | D48: OPEN | E48: 17.09: TCI pending RPN = 92 SOMBP = 0 SHP =1 | G48: Low | H48: 45811 | I48: {=IFERROR(_xlfn.TEXTJOIN(" / ", TRUE, IF(OWNER_LIST[Owner Name]=C_1[[#This Row],[OWNER NAME 1]], OWNER_LIST[Owner ORG], ""), IF(OWNER_LIST[Owner Name]=C_1[[#This Row],[OWNER NAME 2]], OWNER_LIST[Owner ORG], "")), "")} -> RPN | J48: Martina Maffioletti | R48: =_xlfn.CONCAT(C_1[[#This Row],[ESCALATE]], "-",C_1[[#This Row],[Row_PM]]) -> - | S48: =_xlfn.CONCAT(C_1[[#This Row],[ESCALATE]], "-",C_1[[#This Row],[Notify_PM]]) -> -- | T48: =ROW() -> 48 | U48: =IF(C_1[[#This Row],[OWNER NAME 1]] = "", "", IF(_xlfn.XLOOKUP(C_1[[#This Row],[OWNER NAME 1]],OWNER_LIST[Owner Name], OWNER_LIST[Email], "") = "", "", _xlfn.XLOOKUP(C_1[[#This Row],[OWNER NAME 1]], OWNER_LIST[Owner Name], OWNER_LIST[Email], ""))) -> martina.maffioletti@rpn-sa.ch | V48: =IF(C_1[[#This Row],[OWNER NAME 2]] = "", "", IF(_xlfn.XLOOKUP(C_1[[#This Row],[OWNER NAME 2]],OWNER_LIST[Owner Name], OWNER_LIST[Email], "") = "", "", _xlfn.XLOOKUP(C_1[[#This Row],[OWNER NAME 2]], OWNER_LIST[Owner Name], OWNER_LIST[Email], ""))) | W48: =$A$37 -> C1 | X48: =IF( OR( AND( NOT(ISBLANK(C_1[[#This Row],[DESCRIPTION - INFORMATION LOG]])), C_1[[#This Row],[DESCRIPTION - INFORMATION LOG]] <> "DESCRIPTION - INFORMATION LOG" ), NOT(ISBLANK(C_1[[#This Row],[ACTION REQUIRED]])) ), "Y", "N" ) -> Y
A49: GENERAL | B49: EGGTELSA | C49: ACTION | D49: OPEN | E49: EGGTELSA complains about 11 new INS / VAR impacting Substatial completion | F49: 28.01: RPN to present a syntesis of issues and impact on delay | G49: TOP | H49: 46057 | I49: {=IFERROR(_xlfn.TEXTJOIN(" / ", TRUE, IF(OWNER_LIST[Owner Name]=C_1[[#This Row],[OWNER NAME 1]], OWNER_LIST[Owner ORG], ""), IF(OWNER_LIST[Owner Name]=C_1[[#This Row],[OWNER NAME 2]], OWNER_LIST[Owner ORG], "")), "")} -> RPN | J49: Matteo Naldi | R49: =_xlfn.CONCAT(C_1[[#This Row],[ESCALATE]], "-",C_1[[#This Row],[Row_PM]]) -> - | S49: =_xlfn.CONCAT(C_1[[#This Row],[ESCALATE]], "-",C_1[[#This Row],[Notify_PM]]) -> -- | T49: =ROW() -> 49 | U49: =IF(C_1[[#This Row],[OWNER NAME 1]] = "", "", IF(_xlfn.XLOOKUP(C_1[[#This Row],[OWNER NAME 1]],OWNER_LIST[Owner Name], OWNER_LIST[Email], "") = "", "", _xlfn.XLOOKUP(C_1[[#This Row],[OWNER NAME 1]], OWNER_LIST[Owner Name], OWNER_LIST[Email], ""))) -> matteo.naldi@cmbcarpi.it | V49: =IF(C_1[[#This Row],[OWNER NAME 2]] = "", "", IF(_xlfn.XLOOKUP(C_1[[#This Row],[OWNER NAME 2]],OWNER_LIST[Owner Name], OWNER_LIST[Email], "") = "", "", _xlfn.XLOOKUP(C_1[[#This Row],[OWNER NAME 2]], OWNER_LIST[Owner Name], OWNER_LIST[Email], ""))) | W49: =$A$37 -> C1 | X49: =IF( OR( AND( NOT(ISBLANK(C_1[[#This Row],[DESCRIPTION - INFORMATION LOG]])), C_1[[#This Row],[DESCRIPTION - INFORMATION LOG]] <> "DESCRIPTION - INFORMATION LOG" ), NOT(ISBLANK(C_1[[#This Row],[ACTION REQUIRED]])) ), "Y", "N" ) -> Y
A50: GENERAL | B50: FIRE MATRIX | C50: INFO | D50: OPEN | E50: 03.12: meeting took place SBIS/ ENERGY MANAGEMENT 03.12: EGGTELSA needs 2month of works after Fire Matrix is approved 09.12: ENERGY MANAGEMENT provided info, pending SBIS 07.01: Fire Matrix have been uploaded on Pmweb, MEP approved as noted 14.01: Approved as noted (some doors missing) 17.02: FIRE MATRIX has been uploaded 21.02: phase.14 comments have been Uploaded. Status R&R (Minor comments, Technical issues are approved) | F50: 21.01: RPN/ SBIS to update per comments 28.01: RPN to submit 11.02: RPN to submit on 11.02 18.02: SOMBP/ SHP to update 23.02: RPN to assess +/- 05.03 | G50: TOP | H50: 46086 | I50: {=IFERROR(_xlfn.TEXTJOIN(" / ", TRUE, IF(OWNER_LIST[Owner Name]=C_1[[#This Row],[OWNER NAME 1]], OWNER_LIST[Owner ORG], ""), IF(OWNER_LIST[Owner Name]=C_1[[#This Row],[OWNER NAME 2]], OWNER_LIST[Owner ORG], "")), "")} -> RPN | J50: Federica Brunone | R50: =_xlfn.CONCAT(C_1[[#This Row],[ESCALATE]], "-",C_1[[#This Row],[Row_PM]]) -> - | S50: =_xlfn.CONCAT(C_1[[#This Row],[ESCALATE]], "-",C_1[[#This Row],[Notify_PM]]) -> -- | T50: =ROW() -> 50 | U50: =IF(C_1[[#This Row],[OWNER NAME 1]] = "", "", IF(_xlfn.XLOOKUP(C_1[[#This Row],[OWNER NAME 1]],OWNER_LIST[Owner Name], OWNER_LIST[Email], "") = "", "", _xlfn.XLOOKUP(C_1[[#This Row],[OWNER NAME 1]], OWNER_LIST[Owner Name], OWNER_LIST[Email], ""))) -> federica.brunone@cmbcarpi.it | V50: =IF(C_1[[#This Row],[OWNER NAME 2]] = "", "", IF(_xlfn.XLOOKUP(C_1[[#This Row],[OWNER NAME 2]],OWNER_LIST[Owner Name], OWNER_LIST[Email], "") = "", "", _xlfn.XLOOKUP(C_1[[#This Row],[OWNER NAME 2]], OWNER_LIST[Owner Name], OWNER_LIST[Email], ""))) | W50: =$A$37 -> C1 | X50: =IF( OR( AND( NOT(ISBLANK(C_1[[#This Row],[DESCRIPTION - INFORMATION LOG]])), C_1[[#This Row],[DESCRIPTION - INFORMATION LOG]] <> "DESCRIPTION - INFORMATION LOG" ), NOT(ISBLANK(C_1[[#This Row],[ACTION REQUIRED]])) ), "Y", "N" ) -> Y
A51: GENERAL | B51: FIRE HOSES | C51: ACTION | D51: OPEN | E51: 18.02: RPN instructed to PXT to reinstalled Fire hoses at Level 1 & 2 | F51: 18.02: Fire hoses to be T&C + certified PXT to submit report | G51: High | H51: 46142 | I51: {=IFERROR(_xlfn.TEXTJOIN(" / ", TRUE, IF(OWNER_LIST[Owner Name]=C_1[[#This Row],[OWNER NAME 1]], OWNER_LIST[Owner ORG], ""), IF(OWNER_LIST[Owner Name]=C_1[[#This Row],[OWNER NAME 2]], OWNER_LIST[Owner ORG], "")), "")} -> RPN / RPN | J51: Martina Maffioletti | K51: Amos Anderini | R51: =_xlfn.CONCAT(C_1[[#This Row],[ESCALATE]], "-",C_1[[#This Row],[Row_PM]]) -> - | S51: =_xlfn.CONCAT(C_1[[#This Row],[ESCALATE]], "-",C_1[[#This Row],[Notify_PM]]) -> -- | T51: =ROW() -> 51 | U51: =IF(C_1[[#This Row],[OWNER NAME 1]] = "", "", IF(_xlfn.XLOOKUP(C_1[[#This Row],[OWNER NAME 1]],OWNER_LIST[Owner Name], OWNER_LIST[Email], "") = "", "", _xlfn.XLOOKUP(C_1[[#This Row],[OWNER NAME 1]], OWNER_LIST[Owner Name], OWNER_LIST[Email], ""))) -> martina.maffioletti@rpn-sa.ch | V51: =IF(C_1[[#This Row],[OWNER NAME 2]] = "", "", IF(_xlfn.XLOOKUP(C_1[[#This Row],[OWNER NAME 2]],OWNER_LIST[Owner Name], OWNER_LIST[Email], "") = "", "", _xlfn.XLOOKUP(C_1[[#This Row],[OWNER NAME 2]], OWNER_LIST[Owner Name], OWNER_LIST[Email], ""))) -> amos.anderini@rpn-sa.ch | W51: =$A$37 -> C1 | X51: =IF( OR( AND( NOT(ISBLANK(C_1[[#This Row],[DESCRIPTION - INFORMATION LOG]])), C_1[[#This Row],[DESCRIPTION - INFORMATION LOG]] <> "DESCRIPTION - INFORMATION LOG" ), NOT(ISBLANK(C_1[[#This Row],[ACTION REQUIRED]])) ), "Y", "N" ) -> Y
A52: GENERAL | B52: FIRE FIGHTER ROUTE - INS 421 - VAR 536 | C52: ACTION | D52: OPEN | E52: 23.12: Step 4 has been submitted. 28.01: RPN planned completion of works by begining of march. | F52: 21.01: RPN to plan execution in AC and S1 | G52: High | H52: 46061 | I52: {=IFERROR(_xlfn.TEXTJOIN(" / ", TRUE, IF(OWNER_LIST[Owner Name]=C_1[[#This Row],[OWNER NAME 1]], OWNER_LIST[Owner ORG], ""), IF(OWNER_LIST[Owner Name]=C_1[[#This Row],[OWNER NAME 2]], OWNER_LIST[Owner ORG], "")), "")} -> RPN | J52: Matteo Naldi | R52: =_xlfn.CONCAT(C_1[[#This Row],[ESCALATE]], "-",C_1[[#This Row],[Row_PM]]) -> - | S52: =_xlfn.CONCAT(C_1[[#This Row],[ESCALATE]], "-",C_1[[#This Row],[Notify_PM]]) -> -- | T52: =ROW() -> 52 | U52: =IF(C_1[[#This Row],[OWNER NAME 1]] = "", "", IF(_xlfn.XLOOKUP(C_1[[#This Row],[OWNER NAME 1]],OWNER_LIST[Owner Name], OWNER_LIST[Email], "") = "", "", _xlfn.XLOOKUP(C_1[[#This Row],[OWNER NAME 1]], OWNER_LIST[Owner Name], OWNER_LIST[Email], ""))) -> matteo.naldi@cmbcarpi.it | V52: =IF(C_1[[#This Row],[OWNER NAME 2]] = "", "", IF(_xlfn.XLOOKUP(C_1[[#This Row],[OWNER NAME 2]],OWNER_LIST[Owner Name], OWNER_LIST[Email], "") = "", "", _xlfn.XLOOKUP(C_1[[#This Row],[OWNER NAME 2]], OWNER_LIST[Owner Name], OWNER_LIST[Email], ""))) | W52: =$A$37 -> C1 | X52: =IF( OR( AND( NOT(ISBLANK(C_1[[#This Row],[DESCRIPTION - INFORMATION LOG]])), C_1[[#This Row],[DESCRIPTION - INFORMATION LOG]] <> "DESCRIPTION - INFORMATION LOG" ), NOT(ISBLANK(C_1[[#This Row],[ACTION REQUIRED]])) ), "Y", "N" ) -> Y
...

Sheet VARIATIONS
A1: Variation # | B1: Variation Name | C1: Section | D1: Administrative Status of the Variations (Agreed / Determined, Cancelled, In Progress, To be issued) | E1: Critical
A2: R-VAR-0017 | B2: SECURITY REVOLVING DOORS AND LOCKDOWN (PMI 026-027) | C2: ALL | D2: Agreed / Detemined
A3: R-VAR-0025 | B3: POSTAL SMART LOCKERS (PMI 031) (SSet 344) | C3: S1/C/AC/B | D3: Agreed / Detemined
A4: R-VAR-0031 | B4: GLAZED PARTITIONS FIRE RESISTANCE (SSet 327) | C4: ALL | D4: Agreed / Detemined
A5: R-VAR-0034 | B5: DOOR UPDATE BUILDINGS AC, B, S (SSet 323) | C5: ALL | D5: Agreed / Detemined
A6: R-VAR-0040 | B6: RESTAURATION OF HERITAGE FURNITURE (prov sum release) | C6: ALL | D6: Agreed / Detemined
A7: R-VAR-0051 | B7: FIRE SUPPRESSION SYSTEM (prov sum adjustement) | C7: ALL | D7: Agreed / Detemined
A8: R-VAR-0062 | B8: REPLACEMENT OF ASCENDER BY AQUILON | C8: ALL | D8: Agreed / Detemined
A9: R-VAR-0063 | B9: AH Interpreter Booth Changes - Equipment | C9: ALL | D9: Agreed / Detemined
A10: R-VAR-0072 | B10: AV BC INFRASTR OPTIMISATION (PMI 030) | C10: ALL | D10: Agreed / Detemined
A11: R-VAR-0077 | B11: AV MODIFS FOR SECTION C | C11: C | D11: Agreed / Detemined
A12: R-VAR-0084 | B12: NEW GENERATION BADGE READERS | C12: ALL | D12: Agreed / Detemined
A13: R-VAR-0089 | B13: HVAC CHANGES SALLE C6, TV STUDIO AND ATTENUATORS | C13: C | D13: Agreed / Detemined
... A101: R-VAR-0604 | B101: BLDG C PRESS BAR COUNTER TOP | C101: C | D101: Delay
A102: R-VAR-0611 | B102: BLDS A, AB, B & C WINDOW FRAMES | C102: AB/B/C | D102: To be issued | E102: Critical
A103: R-VAR-0612 | B103: VAR 173 revision Overall Broadcast (broadcast, lighting and services included) | C103: B/C | D103: To be issued
A104: R-VAR-0618 | B104: Bldg C Salle 1 Emergency Lighting | C104: C | D104: Delay
A105: R-VAR-0624 | B105: Bldg C Electrical panel board F15/2 | C105: C | D105: To be issued
A106: R-VAR-0625 | B106: Bldg C Electrical panel board F15 and cabling replacing | C106: C | D106: In Progress
A107: R-VAR-0628 | B107: Council Chamber AV - to check if eligible | C107: C | D107: To be issued
A108: R-VAR-0629 | B108: Door C5 cafeteria logistic adjustment (Bldg E catering BC) | C108: C | D108: To be issued
A109: R-VAR-0631 | B109: BLDG C – L00 – Existing Windows Wooden Frame | C109: C | D109: To be issued

Sheet Bldg C - UBS
A1: # | B1: MEETING AGENDA
A2: A | B2: MEETING DETAILS
B3: MEETING. | E3: PRODUCTION
B4: WEEK NO. | E4: =WEEKNUM(E6) -> 28
B5: SECTION | E5: C
B6: DATE | E6: 45850
B7: TIME | E7: 0.45833333
B8: LOCATION | E8: Building C : C-300
B9: PURPOSE | E9: - To support and protect the Production Plan - To strive for improved Production Plan stability and predictability.
B10: NEXT MEETING | E10: =E6+7 -> 45857
A12: B | B12: STAKEHOLDERS | C12: Org. | D12: In Attendance | E12: Name | F12: Column1
B13: =IF(ISBLANK(E13), "", INDEX(OWNER_LIST[Role], MATCH(E13,OWNER_LIST[Owner Name], 0))) -> Senior Architect | C13: =IF(ISBLANK(E13), "", INDEX(OWNER_LIST[Owner ORG], MATCH(E13,OWNER_LIST[Owner Name], 0))) -> SHP | D13: Yes | E13: Samuel Wilson
B14: =IF(ISBLANK(E14), "", INDEX(OWNER_LIST[Role], MATCH(E14,OWNER_LIST[Owner Name], 0))) -> Design Manager (DM) | C14: =IF(ISBLANK(E14), "", INDEX(OWNER_LIST[Owner ORG], MATCH(E14,OWNER_LIST[Owner Name], 0))) -> SHP | D14: Yes | E14: Jean-Mathieu Ferre
B15: =IF(ISBLANK(E15), "", INDEX(OWNER_LIST[Role], MATCH(E15,OWNER_LIST[Owner Name], 0))) -> Security Site Construction Management | C15: =IF(ISBLANK(E15), "", INDEX(OWNER_LIST[Owner ORG], MATCH(E15,OWNER_LIST[Owner Name], 0))) -> SHP | D15: Yes | E15: Cinzia Porracin
B16: =IF(ISBLANK(E16), "", INDEX(OWNER_LIST[Role], MATCH(E16,OWNER_LIST[Owner Name], 0))) -> Move Specialist / Doc Controller | C16: =IF(ISBLANK(E16), "", INDEX(OWNER_LIST[Owner ORG], MATCH(E16,OWNER_LIST[Owner Name], 0))) -> RPN | D16: No | E16: Martina Maffioletti | F16: Agathe
B17: =IF(ISBLANK(E17), "", INDEX(OWNER_LIST[Role], MATCH(E17,OWNER_LIST[Owner Name], 0))) | C17: =IF(ISBLANK(E17), "", INDEX(OWNER_LIST[Owner ORG], MATCH(E17,OWNER_LIST[Owner Name], 0))) | D17: No | F17: Arnaud | H17: ºº
B18: =IF(ISBLANK(E18), "", INDEX(OWNER_LIST[Role], MATCH(E18,OWNER_LIST[Owner Name], 0))) | C18: =IF(ISBLANK(E18), "", INDEX(OWNER_LIST[Owner ORG], MATCH(E18,OWNER_LIST[Owner Name], 0))) | D18: No | F18: arnaud
B19: =IF(ISBLANK(E19), "", INDEX(OWNER_LIST[Role], MATCH(E19,OWNER_LIST[Owner Name], 0))) | C19: =IF(ISBLANK(E19), "", INDEX(OWNER_LIST[Owner ORG], MATCH(E19,OWNER_LIST[Owner Name], 0))) | D19: No
B20: =IF(ISBLANK(E20), "", INDEX(OWNER_LIST[Role], MATCH(E20,OWNER_LIST[Owner Name], 0))) | C20: =IF(ISBLANK(E20), "", INDEX(OWNER_LIST[Owner ORG], MATCH(E20,OWNER_LIST[Owner Name], 0))) | D20: No
B21: =IF(ISBLANK(E21), "", INDEX(OWNER_LIST[Role], MATCH(E21,OWNER_LIST[Owner Name], 0))) | C21: =IF(ISBLANK(E21), "", INDEX(OWNER_LIST[Owner ORG], MATCH(E21,OWNER_LIST[Owner Name], 0))) | D21: No
B22: =IF(ISBLANK(E22), "", INDEX(OWNER_LIST[Role], MATCH(E22,OWNER_LIST[Owner Name], 0))) | C22: =IF(ISBLANK(E22), "", INDEX(OWNER_LIST[Owner ORG], MATCH(E22,OWNER_LIST[Owner Name], 0))) | D22: No
B23: =IF(ISBLANK(E23), "", INDEX(OWNER_LIST[Role], MATCH(E23,OWNER_LIST[Owner Name], 0))) | C23: =IF(ISBLANK(E23), "", INDEX(OWNER_LIST[Owner ORG], MATCH(E23,OWNER_LIST[Owner Name], 0))) | D23: No
A25: C1 | B25: MEETING TOPIC | C25: ACTION - INFO | D25: STATUS | E25: DESCRIPTION - INFORMATION LOG | F25: ACTION REQUIRED | G25: PRIORITY | H25: DUE DATE | I25: OWNER ORG. | J25: OWNER NAME 1 | K25: OWNER NAME 2 | L25: DISCIPLINE | M25: DATE LOGGED | N25: DATE CLOSED | O25: ESCALATE | P25: Note | Q25: Row_PM | R25: Notify_PM | S25: Condition_PM | T25: ROW | U25: Email_Name_1 | V25: Email_Name_2 | W25: SECTION | X25: Nonull
A26: C_1 | B26: HEALTH & SAFETY | R26: =_xlfn.CONCAT(C_1_6[[#This Row],[ESCALATE]], "-",C_1_6[[#This Row],[Row_PM]]) -> - | S26: =_xlfn.CONCAT(C_1_6[[#This Row],[ESCALATE]], "-",C_1_6[[#This Row],[Notify_PM]]) -> - - | T26: =ROW() -> 26 | U26: =IF(C_1_6[[#This Row],[OWNER NAME 1]] = "", "", IF(_xlfn.XLOOKUP(C_1_6[[#This Row],[OWNER NAME 1]],OWNER_LIST[Owner Name], OWNER_LIST[Email], "") = "", "", _xlfn.XLOOKUP(C_1_6[[#This Row],[OWNER NAME 1]], OWNER_LIST[Owner Name], OWNER_LIST[Email], ""))) | V26: =IF(C_1_6[[#This Row],[OWNER NAME 2]] = "", "", IF(_xlfn.XLOOKUP(C_1_6[[#This Row],[OWNER NAME 2]],OWNER_LIST[Owner Name], OWNER_LIST[Email], "") = "", "", _xlfn.XLOOKUP(C_1_6[[#This Row],[OWNER NAME 2]], OWNER_LIST[Owner Name], OWNER_LIST[Email], ""))) | W26: =$A$25 -> C1 | X26: =IF(AND(NOT(ISBLANK(C_1_6[[#This Row],[ACTION - INFO]])),C_1_6[[#This Row],[ACTION - INFO]] <> "ACTION - INFO"),"Y","N") -> N
I27: {=IFERROR(_xlfn.TEXTJOIN(" / ", TRUE, IF(OWNER_LIST[Owner Name]=C_1_6[[#This Row],[OWNER NAME 1]], OWNER_LIST[Owner ORG], ""), IF(OWNER_LIST[Owner Name]=C_1_6[[#This Row],[OWNER NAME 2]], OWNER_LIST[Owner ORG], "")), "")} | R27: =_xlfn.CONCAT(C_1_6[[#This Row],[ESCALATE]], "-",C_1_6[[#This Row],[Row_PM]]) -> - | S27: =_xlfn.CONCAT(C_1_6[[#This Row],[ESCALATE]], "-",C_1_6[[#This Row],[Notify_PM]]) -> -- | T27: =ROW() -> 27 | U27: =IF(C_1_6[[#This Row],[OWNER NAME 1]] = "", "", IF(_xlfn.XLOOKUP(C_1_6[[#This Row],[OWNER NAME 1]],OWNER_LIST[Owner Name], OWNER_LIST[Email], "") = "", "", _xlfn.XLOOKUP(C_1_6[[#This Row],[OWNER NAME 1]], OWNER_LIST[Owner Name], OWNER_LIST[Email], ""))) | V27: =IF(C_1_6[[#This Row],[OWNER NAME 2]] = "", "", IF(_xlfn.XLOOKUP(C_1_6[[#This Row],[OWNER NAME 2]],OWNER_LIST[Owner Name], OWNER_LIST[Email], "") = "", "", _xlfn.XLOOKUP(C_1_6[[#This Row],[OWNER NAME 2]], OWNER_LIST[Owner Name], OWNER_LIST[Email], ""))) | W27: =$A$25 -> C1 | X27: =IF(AND(NOT(ISBLANK(C_1_6[[#This Row],[ACTION - INFO]])),C_1_6[[#This Row],[ACTION - INFO]] <> "ACTION - INFO"),"Y","N") -> N
I28: {=IFERROR(_xlfn.TEXTJOIN(" / ", TRUE, IF(OWNER_LIST[Owner Name]=C_1_6[[#This Row],[OWNER NAME 1]], OWNER_LIST[Owner ORG], ""), IF(OWNER_LIST[Owner Name]=C_1_6[[#This Row],[OWNER NAME 2]], OWNER_LIST[Owner ORG], "")), "")} | R28: =_xlfn.CONCAT(C_1_6[[#This Row],[ESCALATE]], "-",C_1_6[[#This Row],[Row_PM]]) -> - | S28: =_xlfn.CONCAT(C_1_6[[#This Row],[ESCALATE]], "-",C_1_6[[#This Row],[Notify_PM]]) -> -- | T28: =ROW() -> 28 | U28: =IF(C_1_6[[#This Row],[OWNER NAME 1]] = "", "", IF(_xlfn.XLOOKUP(C_1_6[[#This Row],[OWNER NAME 1]],OWNER_LIST[Owner Name], OWNER_LIST[Email], "") = "", "", _xlfn.XLOOKUP(C_1_6[[#This Row],[OWNER NAME 1]], OWNER_LIST[Owner Name], OWNER_LIST[Email], ""))) | V28: =IF(C_1_6[[#This Row],[OWNER NAME 2]] = "", "", IF(_xlfn.XLOOKUP(C_1_6[[#This Row],[OWNER NAME 2]],OWNER_LIST[Owner Name], OWNER_LIST[Email], "") = "", "", _xlfn.XLOOKUP(C_1_6[[#This Row],[OWNER NAME 2]], OWNER_LIST[Owner Name], OWNER_LIST[Email], ""))) | W28: =$A$25 -> C1 | X28: =IF(AND(NOT(ISBLANK(C_1_6[[#This Row],[ACTION - INFO]])),C_1_6[[#This Row],[ACTION - INFO]] <> "ACTION - INFO"),"Y","N") -> N
A29: C_2 | B29: PRODUCTION | R29: =_xlfn.CONCAT(C_1_6[[#This Row],[ESCALATE]], "-",C_1_6[[#This Row],[Row_PM]]) -> - | S29: =_xlfn.CONCAT(C_1_6[[#This Row],[ESCALATE]], "-",C_1_6[[#This Row],[Notify_PM]]) -> - - | T29: =ROW() -> 29 | U29: =IF(C_1_6[[#This Row],[OWNER NAME 1]] = "", "", IF(_xlfn.XLOOKUP(C_1_6[[#This Row],[OWNER NAME 1]],OWNER_LIST[Owner Name], OWNER_LIST[Email], "") = "", "", _xlfn.XLOOKUP(C_1_6[[#This Row],[OWNER NAME 1]], OWNER_LIST[Owner Name], OWNER_LIST[Email], ""))) | V29: =IF(C_1_6[[#This Row],[OWNER NAME 2]] = "", "", IF(_xlfn.XLOOKUP(C_1_6[[#This Row],[OWNER NAME 2]],OWNER_LIST[Owner Name], OWNER_LIST[Email], "") = "", "", _xlfn.XLOOKUP(C_1_6[[#This Row],[OWNER NAME 2]], OWNER_LIST[Owner Name], OWNER_LIST[Email], ""))) | W29: =$A$25 -> C1 | X29: =IF(AND(NOT(ISBLANK(C_1_6[[#This Row],[ACTION - INFO]])),C_1_6[[#This Row],[ACTION - INFO]] <> "ACTION - INFO"),"Y","N") -> N
B30: UBS start of finishing works | C30: ACTION | D30: OPEN | E30: 12.07: By mid january, UBS to start finishes works by mid January. +/- 2 months | G30: Medium | H30: 45887 | I30: {=IFERROR(_xlfn.TEXTJOIN(" / ", TRUE, IF(OWNER_LIST[Owner Name]=C_1_6[[#This Row],[OWNER NAME 1]], OWNER_LIST[Owner ORG], ""), IF(OWNER_LIST[Owner Name]=C_1_6[[#This Row],[OWNER NAME 2]], OWNER_LIST[Owner ORG], "")), "")} | R30: =_xlfn.CONCAT(C_1_6[[#This Row],[ESCALATE]], "-",C_1_6[[#This Row],[Row_PM]]) -> - | S30: =_xlfn.CONCAT(C_1_6[[#This Row],[ESCALATE]], "-",C_1_6[[#This Row],[Notify_PM]]) -> -- | T30: =ROW() -> 30 | U30: =IF(C_1_6[[#This Row],[OWNER NAME 1]] = "", "", IF(_xlfn.XLOOKUP(C_1_6[[#This Row],[OWNER NAME 1]],OWNER_LIST[Owner Name], OWNER_LIST[Email], "") = "", "", _xlfn.XLOOKUP(C_1_6[[#This Row],[OWNER NAME 1]], OWNER_LIST[Owner Name], OWNER_LIST[Email], ""))) | V30: =IF(C_1_6[[#This Row],[OWNER NAME 2]] = "", "", IF(_xlfn.XLOOKUP(C_1_6[[#This Row],[OWNER NAME 2]],OWNER_LIST[Owner Name], OWNER_LIST[Email], "") = "", "", _xlfn.XLOOKUP(C_1_6[[#This Row],[OWNER NAME 2]], OWNER_LIST[Owner Name], OWNER_LIST[Email], ""))) | W30: =$A$25 -> C1 | X30: =IF(AND(NOT(ISBLANK(C_1_6[[#This Row],[ACTION - INFO]])),C_1_6[[#This Row],[ACTION - INFO]] <> "ACTION - INFO"),"Y","N") -> Y
B31: UBS operation | C31: ACTION | D31: OPEN | E31: 12.07: By 16.03.2026. Worth case 01.07.2026 | G31: Medium | I31: {=IFERROR(_xlfn.TEXTJOIN(" / ", TRUE, IF(OWNER_LIST[Owner Name]=C_1_6[[#This Row],[OWNER NAME 1]], OWNER_LIST[Owner ORG], ""), IF(OWNER_LIST[Owner Name]=C_1_6[[#This Row],[OWNER NAME 2]], OWNER_LIST[Owner ORG], "")), "")} | R31: =_xlfn.CONCAT(C_1_6[[#This Row],[ESCALATE]], "-",C_1_6[[#This Row],[Row_PM]]) -> - | S31: =_xlfn.CONCAT(C_1_6[[#This Row],[ESCALATE]], "-",C_1_6[[#This Row],[Notify_PM]]) -> -- | T31: =ROW() -> 31 | U31: =IF(C_1_6[[#This Row],[OWNER NAME 1]] = "", "", IF(_xlfn.XLOOKUP(C_1_6[[#This Row],[OWNER NAME 1]],OWNER_LIST[Owner Name], OWNER_LIST[Email], "") = "", "", _xlfn.XLOOKUP(C_1_6[[#This Row],[OWNER NAME 1]], OWNER_LIST[Owner Name], OWNER_LIST[Email], ""))) | V31: =IF(C_1_6[[#This Row],[OWNER NAME 2]] = "", "", IF(_xlfn.XLOOKUP(C_1_6[[#This Row],[OWNER NAME 2]],OWNER_LIST[Owner Name], OWNER_LIST[Email], "") = "", "", _xlfn.XLOOKUP(C_1_6[[#This Row],[OWNER NAME 2]], OWNER_LIST[Owner Name], OWNER_LIST[Email], ""))) | W31: =$A$25 -> C1 | X31: =IF(AND(NOT(ISBLANK(C_1_6[[#This Row],[ACTION - INFO]])),C_1_6[[#This Row],[ACTION - INFO]] <> "ACTION - INFO"),"Y","N") -> Y
B32: OPEN HOUSE | E32: 12.07: Their will be an Open House day, UBS will not be invited | G32: Medium | H32: 45853 | I32: {=IFERROR(_xlfn.TEXTJOIN(" / ", TRUE, IF(OWNER_LIST[Owner Name]=C_1_6[[#This Row],[OWNER NAME 1]], OWNER_LIST[Owner ORG], ""), IF(OWNER_LIST[Owner Name]=C_1_6[[#This Row],[OWNER NAME 2]], OWNER_LIST[Owner ORG], "")), "")} -> RPN / RPN | J32: Matteo Naldi | K32: Simone Conti | R32: =_xlfn.CONCAT(C_1_6[[#This Row],[ESCALATE]], "-",C_1_6[[#This Row],[Row_PM]]) -> - | S32: =_xlfn.CONCAT(C_1_6[[#This Row],[ESCALATE]], "-",C_1_6[[#This Row],[Notify_PM]]) -> -- | T32: =ROW() -> 32 | U32: =IF(C_1_6[[#This Row],[OWNER NAME 1]] = "", "", IF(_xlfn.XLOOKUP(C_1_6[[#This Row],[OWNER NAME 1]],OWNER_LIST[Owner Name], OWNER_LIST[Email], "") = "", "", _xlfn.XLOOKUP(C_1_6[[#This Row],[OWNER NAME 1]], OWNER_LIST[Owner Name], OWNER_LIST[Email], ""))) -> matteo.naldi@cmbcarpi.it | V32: =IF(C_1_6[[#This Row],[OWNER NAME 2]] = "", "", IF(_xlfn.XLOOKUP(C_1_6[[#This Row],[OWNER NAME 2]],OWNER_LIST[Owner Name], OWNER_LIST[Email], "") = "", "", _xlfn.XLOOKUP(C_1_6[[#This Row],[OWNER NAME 2]], OWNER_LIST[Owner Name], OWNER_LIST[Email], ""))) -> simone.conti@cmbcarpi.it | W32: =$A$25 -> C1 | X32: =IF(AND(NOT(ISBLANK(C_1_6[[#This Row],[ACTION - INFO]])),C_1_6[[#This Row],[ACTION - INFO]] <> "ACTION - INFO"),"Y","N") -> N
B33: Next meeting | E33: 12.07: Friday 26.09 | G33: Medium | H33: 45811 | I33: {=IFERROR(_xlfn.TEXTJOIN(" / ", TRUE, IF(OWNER_LIST[Owner Name]=C_1_6[[#This Row],[OWNER NAME 1]], OWNER_LIST[Owner ORG], ""), IF(OWNER_LIST[Owner Name]=C_1_6[[#This Row],[OWNER NAME 2]], OWNER_LIST[Owner ORG], "")), "")} -> RPN / SHP | J33: Davide Cirillo | K33: Didier Dequatre | R33: =_xlfn.CONCAT(C_1_6[[#This Row],[ESCALATE]], "-",C_1_6[[#This Row],[Row_PM]]) -> - | S33: =_xlfn.CONCAT(C_1_6[[#This Row],[ESCALATE]], "-",C_1_6[[#This Row],[Notify_PM]]) -> -- | T33: =ROW() -> 33 | U33: =IF(C_1_6[[#This Row],[OWNER NAME 1]] = "", "", IF(_xlfn.XLOOKUP(C_1_6[[#This Row],[OWNER NAME 1]],OWNER_LIST[Owner Name], OWNER_LIST[Email], "") = "", "", _xlfn.XLOOKUP(C_1_6[[#This Row],[OWNER NAME 1]], OWNER_LIST[Owner Name], OWNER_LIST[Email], ""))) -> davide.cirillo@cmbcarpi.it | V33: =IF(C_1_6[[#This Row],[OWNER NAME 2]] = "", "", IF(_xlfn.XLOOKUP(C_1_6[[#This Row],[OWNER NAME 2]],OWNER_LIST[Owner Name], OWNER_LIST[Email], "") = "", "", _xlfn.XLOOKUP(C_1_6[[#This Row],[OWNER NAME 2]], OWNER_LIST[Owner Name], OWNER_LIST[Email], ""))) -> didier.dequatre@un.org | W33: =$A$25 -> C1 | X33: =IF(AND(NOT(ISBLANK(C_1_6[[#This Row],[ACTION - INFO]])),C_1_6[[#This Row],[ACTION - INFO]] <> "ACTION - INFO"),"Y","N") -> N
G34: High | H34: 45855 | I34: {=IFERROR(_xlfn.TEXTJOIN(" / ", TRUE, IF(OWNER_LIST[Owner Name]=C_1_6[[#This Row],[OWNER NAME 1]], OWNER_LIST[Owner ORG], ""), IF(OWNER_LIST[Owner Name]=C_1_6[[#This Row],[OWNER NAME 2]], OWNER_LIST[Owner ORG], "")), "")} -> RPN | J34: Jessica Donatelli | R34: =_xlfn.CONCAT(C_1_6[[#This Row],[ESCALATE]], "-",C_1_6[[#This Row],[Row_PM]]) -> - | S34: =_xlfn.CONCAT(C_1_6[[#This Row],[ESCALATE]], "-",C_1_6[[#This Row],[Notify_PM]]) -> -- | T34: =ROW() -> 34 | U34: =IF(C_1_6[[#This Row],[OWNER NAME 1]] = "", "", IF(_xlfn.XLOOKUP(C_1_6[[#This Row],[OWNER NAME 1]],OWNER_LIST[Owner Name], OWNER_LIST[Email], "") = "", "", _xlfn.XLOOKUP(C_1_6[[#This Row],[OWNER NAME 1]], OWNER_LIST[Owner Name], OWNER_LIST[Email], ""))) -> jessica.donatelli@cmbcarpi.it | V34: =IF(C_1_6[[#This Row],[OWNER NAME 2]] = "", "", IF(_xlfn.XLOOKUP(C_1_6[[#This Row],[OWNER NAME 2]],OWNER_LIST[Owner Name], OWNER_LIST[Email], "") = "", "", _xlfn.XLOOKUP(C_1_6[[#This Row],[OWNER NAME 2]], OWNER_LIST[Owner Name], OWNER_LIST[Email], ""))) | W34: =$A$25 -> C1 | X34: =IF(AND(NOT(ISBLANK(C_1_6[[#This Row],[ACTION - INFO]])),C_1_6[[#This Row],[ACTION - INFO]] <> "ACTION - INFO"),"Y","N") -> N
G35: High | I35: {=IFERROR(_xlfn.TEXTJOIN(" / ", TRUE, IF(OWNER_LIST[Owner Name]=C_1_6[[#This Row],[OWNER NAME 1]], OWNER_LIST[Owner ORG], ""), IF(OWNER_LIST[Owner Name]=C_1_6[[#This Row],[OWNER NAME 2]], OWNER_LIST[Owner ORG], "")), "")} -> RPN | J35: Matteo Naldi | R35: =_xlfn.CONCAT(C_1_6[[#This Row],[ESCALATE]], "-",C_1_6[[#This Row],[Row_PM]]) -> - | S35: =_xlfn.CONCAT(C_1_6[[#This Row],[ESCALATE]], "-",C_1_6[[#This Row],[Notify_PM]]) -> -- | T35: =ROW() -> 35 | U35: =IF(C_1_6[[#This Row],[OWNER NAME 1]] = "", "", IF(_xlfn.XLOOKUP(C_1_6[[#This Row],[OWNER NAME 1]],OWNER_LIST[Owner Name], OWNER_LIST[Email], "") = "", "", _xlfn.XLOOKUP(C_1_6[[#This Row],[OWNER NAME 1]], OWNER_LIST[Owner Name], OWNER_LIST[Email], ""))) -> matteo.naldi@cmbcarpi.it | V35: =IF(C_1_6[[#This Row],[OWNER NAME 2]] = "", "", IF(_xlfn.XLOOKUP(C_1_6[[#This Row],[OWNER NAME 2]],OWNER_LIST[Owner Name], OWNER_LIST[Email], "") = "", "", _xlfn.XLOOKUP(C_1_6[[#This Row],[OWNER NAME 2]], OWNER_LIST[Owner Name], OWNER_LIST[Email], ""))) | W35: =$A$25 -> C1 | X35: =IF(AND(NOT(ISBLANK(C_1_6[[#This Row],[ACTION - INFO]])),C_1_6[[#This Row],[ACTION - INFO]] <> "ACTION - INFO"),"Y","N") -> N
R36: =_xlfn.CONCAT(C_1_6[[#This Row],[ESCALATE]], "-",C_1_6[[#This Row],[Row_PM]]) -> - | S36: =_xlfn.CONCAT(C_1_6[[#This Row],[ESCALATE]], "-",C_1_6[[#This Row],[Notify_PM]]) -> -- | T36: =ROW() -> 36 | U36: =IF(C_1_6[[#This Row],[OWNER NAME 1]] = "", "", IF(_xlfn.XLOOKUP(C_1_6[[#This Row],[OWNER NAME 1]],OWNER_LIST[Owner Name], OWNER_LIST[Email], "") = "", "", _xlfn.XLOOKUP(C_1_6[[#This Row],[OWNER NAME 1]], OWNER_LIST[Owner Name], OWNER_LIST[Email], ""))) | V36: =IF(C_1_6[[#This Row],[OWNER NAME 2]] = "", "", IF(_xlfn.XLOOKUP(C_1_6[[#This Row],[OWNER NAME 2]],OWNER_LIST[Owner Name], OWNER_LIST[Email], "") = "", "", _xlfn.XLOOKUP(C_1_6[[#This Row],[OWNER NAME 2]], OWNER_LIST[Owner Name], OWNER_LIST[Email], ""))) | W36: =$A$25 -> C1 | X36: =IF(AND(NOT(ISBLANK(C_1_6[[#This Row],[ACTION - INFO]])),C_1_6[[#This Row],[ACTION - INFO]] <> "ACTION - INFO"),"Y","N") -> N
R37: =_xlfn.CONCAT(C_1_6[[#This Row],[ESCALATE]], "-",C_1_6[[#This Row],[Row_PM]]) -> - | S37: =_xlfn.CONCAT(C_1_6[[#This Row],[ESCALATE]], "-",C_1_6[[#This Row],[Notify_PM]]) -> -- | T37: =ROW() -> 37 | U37: =IF(C_1_6[[#This Row],[OWNER NAME 1]] = "", "", IF(_xlfn.XLOOKUP(C_1_6[[#This Row],[OWNER NAME 1]],OWNER_LIST[Owner Name], OWNER_LIST[Email], "") = "", "", _xlfn.XLOOKUP(C_1_6[[#This Row],[OWNER NAME 1]], OWNER_LIST[Owner Name], OWNER_LIST[Email], ""))) | V37: =IF(C_1_6[[#This Row],[OWNER NAME 2]] = "", "", IF(_xlfn.XLOOKUP(C_1_6[[#This Row],[OWNER NAME 2]],OWNER_LIST[Owner Name], OWNER_LIST[Email], "") = "", "", _xlfn.XLOOKUP(C_1_6[[#This Row],[OWNER NAME 2]], OWNER_LIST[Owner Name], OWNER_LIST[Email], ""))) | W37: =$A$25 -> C1 | X37: =IF(AND(NOT(ISBLANK(C_1_6[[#This Row],[ACTION - INFO]])),C_1_6[[#This Row],[ACTION - INFO]] <> "ACTION - INFO"),"Y","N") -> N
A38: C_3 | B38: ING & COMMISSIONING | I38: {=IFERROR(_xlfn.TEXTJOIN(" / ", TRUE, IF(OWNER_LIST[Owner Name]=C_1_6[[#This Row],[OWNER NAME 1]], OWNER_LIST[Owner ORG], ""), IF(OWNER_LIST[Owner Name]=C_1_6[[#This Row],[OWNER NAME 2]], OWNER_LIST[Owner ORG], "")), "")} | R38: =_xlfn.CONCAT(C_1_6[[#This Row],[ESCALATE]], "-",C_1_6[[#This Row],[Row_PM]]) -> - | S38: =_xlfn.CONCAT(C_1_6[[#This Row],[ESCALATE]], "-",C_1_6[[#This Row],[Notify_PM]]) -> - - | T38: =ROW() -> 38 | U38: =IF(C_1_6[[#This Row],[OWNER NAME 1]] = "", "", IF(_xlfn.XLOOKUP(C_1_6[[#This Row],[OWNER NAME 1]],OWNER_LIST[Owner Name], OWNER_LIST[Email], "") = "", "", _xlfn.XLOOKUP(C_1_6[[#This Row],[OWNER NAME 1]], OWNER_LIST[Owner Name], OWNER_LIST[Email], ""))) | V38: =IF(C_1_6[[#This Row],[OWNER NAME 2]] = "", "", IF(_xlfn.XLOOKUP(C_1_6[[#This Row],[OWNER NAME 2]],OWNER_LIST[Owner Name], OWNER_LIST[Email], "") = "", "", _xlfn.XLOOKUP(C_1_6[[#This Row],[OWNER NAME 2]], OWNER_LIST[Owner Name], OWNER_LIST[Email], ""))) | W38: =$A$25 -> C1 | X38: =IF(AND(NOT(ISBLANK(C_1_6[[#This Row],[ACTION - INFO]])),C_1_6[[#This Row],[ACTION - INFO]] <> "ACTION - INFO"),"Y","N") -> N
I42: {=IFERROR(_xlfn.TEXTJOIN(" / ", TRUE, IF(OWNER_LIST[Owner Name]=C_1_6[[#This Row],[OWNER NAME 1]], OWNER_LIST[Owner ORG], ""), IF(OWNER_LIST[Owner Name]=C_1_6[[#This Row],[OWNER NAME 2]], OWNER_LIST[Owner ORG], "")), "")} | R42: =_xlfn.CONCAT(C_1_6[[#This Row],[ESCALATE]], "-",C_1_6[[#This Row],[Row_PM]]) -> - | S42: =_xlfn.CONCAT(C_1_6[[#This Row],[ESCALATE]], "-",C_1_6[[#This Row],[Notify_PM]]) -> -- | T42: =ROW() -> 42 | U42: =IF(C_1_6[[#This Row],[OWNER NAME 1]] = "", "", IF(_xlfn.XLOOKUP(C_1_6[[#This Row],[OWNER NAME 1]],OWNER_LIST[Owner Name], OWNER_LIST[Email], "") = "", "", _xlfn.XLOOKUP(C_1_6[[#This Row],[OWNER NAME 1]], OWNER_LIST[Owner Name], OWNER_LIST[Email], ""))) | V42: =IF(C_1_6[[#This Row],[OWNER NAME 2]] = "", "", IF(_xlfn.XLOOKUP(C_1_6[[#This Row],[OWNER NAME 2]],OWNER_LIST[Owner Name], OWNER_LIST[Email], "") = "", "", _xlfn.XLOOKUP(C_1_6[[#This Row],[OWNER NAME 2]], OWNER_LIST[Owner Name], OWNER_LIST[Email], ""))) | W42: =$A$25 -> C1 | X42: =IF(AND(NOT(ISBLANK(C_1_6[[#This Row],[ACTION - INFO]])),C_1_6[[#This Row],[ACTION - INFO]] <> "ACTION - INFO"),"Y","N") -> N
I43: {=IFERROR(_xlfn.TEXTJOIN(" / ", TRUE, IF(OWNER_LIST[Owner Name]=C_1_6[[#This Row],[OWNER NAME 1]], OWNER_LIST[Owner ORG], ""), IF(OWNER_LIST[Owner Name]=C_1_6[[#This Row],[OWNER NAME 2]], OWNER_LIST[Owner ORG], "")), "")} | R43: =_xlfn.CONCAT(C_1_6[[#This Row],[ESCALATE]], "-",C_1_6[[#This Row],[Row_PM]]) -> - | S43: =_xlfn.CONCAT(C_1_6[[#This Row],[ESCALATE]], "-",C_1_6[[#This Row],[Notify_PM]]) -> -- | T43: =ROW() -> 43 | U43: =IF(C_1_6[[#This Row],[OWNER NAME 1]] = "", "", IF(_xlfn.XLOOKUP(C_1_6[[#This Row],[OWNER NAME 1]],OWNER_LIST[Owner Name], OWNER_LIST[Email], "") = "", "", _xlfn.XLOOKUP(C_1_6[[#This Row],[OWNER NAME 1]], OWNER_LIST[Owner Name], OWNER_LIST[Email], ""))) | V43: =IF(C_1_6[[#This Row],[OWNER NAME 2]] = "", "", IF(_xlfn.XLOOKUP(C_1_6[[#This Row],[OWNER NAME 2]],OWNER_LIST[Owner Name], OWNER_LIST[Email], "") = "", "", _xlfn.XLOOKUP(C_1_6[[#This Row],[OWNER NAME 2]], OWNER_LIST[Owner Name], OWNER_LIST[Email], ""))) | W43: =$A$25 -> C1 | X43: =IF(AND(NOT(ISBLANK(C_1_6[[#This Row],[ACTION - INFO]])),C_1_6[[#This Row],[ACTION - INFO]] <> "ACTION - INFO"),"Y","N") -> N
I44: {=IFERROR(_xlfn.TEXTJOIN(" / ", TRUE, IF(OWNER_LIST[Owner Name]=C_1_6[[#This Row],[OWNER NAME 1]], OWNER_LIST[Owner ORG], ""), IF(OWNER_LIST[Owner Name]=C_1_6[[#This Row],[OWNER NAME 2]], OWNER_LIST[Owner ORG], "")), "")} | R44: =_xlfn.CONCAT(C_1_6[[#This Row],[ESCALATE]], "-",C_1_6[[#This Row],[Row_PM]]) -> - | S44: =_xlfn.CONCAT(C_1_6[[#This Row],[ESCALATE]], "-",C_1_6[[#This Row],[Notify_PM]]) -> -- | T44: =ROW() -> 44 | U44: =IF(C_1_6[[#This Row],[OWNER NAME 1]] = "", "", IF(_xlfn.XLOOKUP(C_1_6[[#This Row],[OWNER NAME 1]],OWNER_LIST[Owner Name], OWNER_LIST[Email], "") = "", "", _xlfn.XLOOKUP(C_1_6[[#This Row],[OWNER NAME 1]], OWNER_LIST[Owner Name], OWNER_LIST[Email], ""))) | V44: =IF(C_1_6[[#This Row],[OWNER NAME 2]] = "", "", IF(_xlfn.XLOOKUP(C_1_6[[#This Row],[OWNER NAME 2]],OWNER_LIST[Owner Name], OWNER_LIST[Email], "") = "", "", _xlfn.XLOOKUP(C_1_6[[#This Row],[OWNER NAME 2]], OWNER_LIST[Owner Name], OWNER_LIST[Email], ""))) | W44: =$A$25 -> C1 | X44: =IF(AND(NOT(ISBLANK(C_1_6[[#This Row],[ACTION - INFO]])),C_1_6[[#This Row],[ACTION - INFO]] <> "ACTION - INFO"),"Y","N") -> N
I45: {=IFERROR(_xlfn.TEXTJOIN(" / ", TRUE, IF(OWNER_LIST[Owner Name]=C_1_6[[#This Row],[OWNER NAME 1]], OWNER_LIST[Owner ORG], ""), IF(OWNER_LIST[Owner Name]=C_1_6[[#This Row],[OWNER NAME 2]], OWNER_LIST[Owner ORG], "")), "")} | R45: =_xlfn.CONCAT(C_1_6[[#This Row],[ESCALATE]], "-",C_1_6[[#This Row],[Row_PM]]) -> - | S45: =_xlfn.CONCAT(C_1_6[[#This Row],[ESCALATE]], "-",C_1_6[[#This Row],[Notify_PM]]) -> -- | T45: =ROW() -> 45 | U45: =IF(C_1_6[[#This Row],[OWNER NAME 1]] = "", "", IF(_xlfn.XLOOKUP(C_1_6[[#This Row],[OWNER NAME 1]],OWNER_LIST[Owner Name], OWNER_LIST[Email], "") = "", "", _xlfn.XLOOKUP(C_1_6[[#This Row],[OWNER NAME 1]], OWNER_LIST[Owner Name], OWNER_LIST[Email], ""))) | V45: =IF(C_1_6[[#This Row],[OWNER NAME 2]] = "", "", IF(_xlfn.XLOOKUP(C_1_6[[#This Row],[OWNER NAME 2]],OWNER_LIST[Owner Name], OWNER_LIST[Email], "") = "", "", _xlfn.XLOOKUP(C_1_6[[#This Row],[OWNER NAME 2]], OWNER_LIST[Owner Name], OWNER_LIST[Email], ""))) | W45: =$A$25 -> C1 | X45: =IF(AND(NOT(ISBLANK(C_1_6[[#This Row],[ACTION - INFO]])),C_1_6[[#This Row],[ACTION - INFO]] <> "ACTION - INFO"),"Y","N") -> N
...

Sheet IT_Network_elevation
A1: Prerequisites to handover the switches: | C1: Action
A2: 1 | B2: Rack elevations are approved in PMWeb;
A3: 2 | B3: All works inside the TRs are finalized (except for the installation of the switches);
A4: 3 | B4: The TRs are cleaned and dust free;
A5: 4 | B5: If there are works generating dust in areas close to the TRs, the TRs have to be protected against the dust;
A6: 5 | B6: The TRs’ doors have temporary locks (until the access control is activated).
A8: Prerequisites to turn on the switches:
A9: 1 | B9: All switches provided to RPN are installed according to the rack elevation provided by RPN;
A10: 2 | B10: TRs are clean. The cleanliness has to be assessed by ICTS during a site visit.
A11: 3 | B11: Keys of the TRs are provided to ICTS;
A12: 4 | B12: The HVAC of the TRs is turned on;
A13: 5 | B13: The protected electricity (UPS) is available in the racks;
A14: 6 | B14: The certification of the optical fibers is approved in PMWeb;
A15: 7 | B15: Optical fiber patch cables are provided to ICTS to connect the switches to the UNOG LAN;

Sheet CLOSED
A1: 6 | B1: CLOSED
A2: C1 | B2: MEETING TOPIC | C2: ACTION - INFO | D2: STATUS | E2: DESCRIPTION - INFORMATION LOG | F2: ACTION REQUIRED | G2: PRIORITY | H2: DUE DATE | I2: OWNER ORG. | J2: OWNER NAME 1 | K2: OWNER NAME 2 | L2: DISCIPLINE | M2: DATE LOGGED | N2: DATE CLOSED | O2: ESCALATE | P2: Note | Q2: Row_PM | R2: Notify_PM | S2: Condition_PM | T2: Row | U2: Email_Name_1 | V2: Email_Name_2 | W2: SECTION | X2: Nonull
A3: VAR 106 | B3: BLDG C ARCHIVE FIRE PROTECTION | D3: CLOSED | E3: - | G3: 0 | N3: 18.07.2024 | S3: - | T3: 118 | U3: 0 | V3: 0 | W3: ActionClosed | X3: N
A4: VAR 138 | B4: BLDG C - ARCHIVES VENTILATION - BASEMENT | D4: CLOSED | E4: C: 12/06/23 | G4: 0 | N4: 18.07.2024 | S4: - | T4: 119 | U4: 0 | V4: 0 | W4: ActionClosed | X4: N
A5: VAR 167 | B5: UPPER WINDOW MOTORIZATION | D5: CLOSED | E5: - | G5: INS 268, INS 326 | N5: 18.07.2024 | S5: - | T5: 120 | U5: 0 | V5: 0 | W5: ActionClosed | X5: N
A6: VAR 180 | B6: BDLG C LB2 PLANTROOM C.0014 | D6: CLOSED | E6: C: 28-Jul-23 | G6: 0 | N6: 18.07.2024 | S6: - | T6: 121 | U6: 0 | V6: 0 | W6: ActionClosed | X6: N
A7: VAR 221 | B7: EMERGENCY SIGNAGE AND LIGHTING UPDATE C | D7: CLOSED | E7: No Info | G7: INS 348 | N7: 45498 | S7: - | T7: 122 | U7: 0 | V7: 0 | W7: ActionClosed | X7: N
A8: VAR 243 | B8: FIRE DETECTION SKYLIGHTS BLDG B and C | D8: CLOSED | E8: - | G8: 0 | S8: - | T8: 123 | U8: 0 | V8: 0 | W8: ActionClosed | X8: N
A9: VAR 249 | B9: Bldg C- SKYLIGHT SECURITY AND LIGHTING CONTROL | D9: CLOSED | E9: - | G9: 0 | S9: - | T9: 124 | U9: 0 | V9: 0 | W9: ActionClosed | X9: N
A10: VAR 260 | B10: BLDGS A / AB / C - INTERPRETER BOOTHS ACOUSTICS | D10: CLOSED | E10: AB: 21/05/2024 C: 23/04/2024 | G10: INS 311 | S10: - | T10: 125 | U10: 0 | V10: 0 | W10: ActionClosed | X10: N
A11: INS 341 | B11: Bldg C fire dampers VAR 138 - Rev 1 | D11: CLOSED | E11: 0 | G11: #N/A | N11: 18.07.2024 | S11: - | T11: 126 | U11: 0 | V11: 0 | W11: ActionClosed | X11: N
A12: VAR 387 | B12: BLDG C BLIND AND MOTORIZED WINDOW BOXES | D12: CLOSED | E12: - | G12: 0 | S12: - | T12: 127 | V12: 0 | W12: ActionClosed | X12: N
A13: VAR 395 | B13: BLDG C - COUNCIL CHAMBER AV RACKS RELOCATION | D13: CLOSED | E13: C: 16-Apr-25 | G13: 0 | N13: 45498 | S13: - | T13: 128 | U13: 0 | V13: 0 | W13: ActionClosed | X13: N
A14: VAR 399 | B14: BLDG C L02 COUNCIL CHAMBER GALLERY EXIT | D14: CLOSED | E14: - | G14: 0 | N14: 18.07.2024 | S14: - | T14: 129 | U14: 0 | V14: 0 | W14: ActionClosed | X14: N
A15: INS 408 | B15: Bldg C - PA speakers L01-L02 - Open Aera Council Chamber - PA speakers | D15: CLOSED | E15: 0 | G15: #N/A | S15: - | T15: 130 | U15: 0 | V15: 0 | W15: ActionClosed | X15: N
A16: VAR 416 | B16: BLDG C EXISTING OPENINGS IN BASEMENTS | D16: CLOSED | E16: - | G16: 0 | N16: 18.07.2024 | S16: - | T16: 131 | U16: 0 | V16: 0 | W16: ActionClosed | X16: N
A17: VAR 426 | B17: BLDG C - IT CABLING | D17: CLOSED | E17: - | G17: 0 | N17: 18.07.2024 | S17: - | T17: 132 | U17: 0 | V17: 0 | W17: ActionClosed | X17: N
A18: INS 409 | B18: Bldg C stair 5 corridors changes | D18: CLOSED | E18: 0 | G18: #N/A | N18: 45498 | S18: - | T18: 133 | U18: 0 | V18: 0 | W18: ActionClosed | X18: N
A19: VAR 449 | B19: BLDG C SENSITIVE ROOMS - SALON RUSSE + LOBBY | D19: CLOSED | E19: No Info | G19: 0 | S19: - | T19: 134 | U19: 0 | V19: 0 | W19: ActionClosed | X19: N
A20: VAR 450 | B20: BLDG C SENSITIVE ROOMS - SALLE 1 AND 2 | D20: CLOSED | E20: - | G20: 0 | M20: 01.10.2024 | S20: - | T20: 135 | U20: 0 | V20: 0 | W20: ActionClosed | X20: N
A21: VAR 474 | B21: BLDG C - ENTRANCE AND PRESS BAR NEW STONE LAYOUT | D21: CLOSED | E21: - | G21: 0 | N21: 18.07.2024 | S21: - | T21: 136 | U21: 0 | V21: 0 | W21: ActionClosed | X21: N
A22: VAR 493 | B22: BLDG C - UNTV DOORS | D22: CLOSED | E22: - | G22: 0 | N22: 6.11.2024 | S22: - | T22: 137 | U22: neil.bradley@un.org | V22: 0 | W22: ActionClosed | X22: N
A23: VAR 494 | B23: BLDG C - UNTV BLINDS | D23: CLOSED | E23: - | G23: 0 | N23: 6.11.2024 | S23: - | T23: 138 | U23: jessica.donatelli@cmbcarpi.it | V23: 0 | W23: ActionClosed | X23: N
A24: VAR 504 | B24: Access control IT room LB1 S1 | D24: CLOSED | E24: No Info | G24: 0 | S24: - | T24: 139 | U24: 0 | V24: 0 | W24: ActionClosed | X24: N
A25: VAR 506 | B25: BDLG C ADDITIONAL FIRE DETECTION DEVICES (CDP) | D25: CLOSED | E25: No Info | G25: 0 | S25: - | T25: 140 | U25: 0 | V25: 0 | W25: ActionClosed | X25: N
B26: Final EL installation for Skylight RFI-0930-b | D26: CLOSED | N26: 18.07.2024 | S26: - | T26: 141 | U26: 0 | V26: 0 | W26: ActionClosed | X26: N
B27: MAG 5.1 - MEP Installation blocked by archives presence | D27: CLOSED | N27: 18.07.2024 | S27: - | T27: 142 | U27: 0 | V27: 0 | W27: ActionClosed | X27: N
B28: Opening for electrical elements to be validated | D28: CLOSED | N28: 18.07.2024 | S28: - | T28: 143 | U28: 0 | V28: 0 | W28: ActionClosed | X28: N
D29: CLOSED | F29: VAR 527 has been issued | S29: - | T29: 144 | U29: 0 | V29: 0 | W29: ActionClosed | X29: N
D30: CLOSED | F30: RPN subcontract to update documents | S30: - | T30: 145 | U30: 0 | V30: 0 | W30: ActionClosed | X30: N
D31: CLOSED | F31: RPN to issue design | S31: - | T31: 146 | U31: 0 | V31: 0 | W31: ActionClosed | X31: N
D32: CLOSED | F32: Subcontractor of roller shutter (Rieder) to provide missing technical informations (dimension & position of motor) | S32: - | T32: 147 | U32: 0 | V32: 0 | W32: ActionClosed | X32: N
D33: CLOSED | F33: RPN to provide the List of equipment. To be confirmed by UNTV | S33: - | T33: 148 | U33: 0 | V33: 0 | W33: ActionClosed | X33: N
D34: CLOSED | F34: Check with UNTV stakeholders whether vision panel in door type C_WD104 can be ommited | M34: 45480 | S34: - | T34: 149 | U34: 0 | V34: 0 | W34: ActionClosed | X34: N
D35: CLOSED | F35: SOMBP to provide sketch | M35: 45510 | S35: - | T35: 150 | U35: 0 | V35: 0 | W35: ActionClosed | X35: N
D36: CLOSED | F36: RPN to fill the gap with bricks, will be considered as exisiting | M36: 45510 | S36: - | T36: 151 | U36: 0 | V36: 0 | W36: ActionClosed | X36: N
D37: CLOSED | F37: RPN confirmed the marble has been stored and will be reinstalled | M37: 45510 | S37: - | T37: 152 | U37: 0 | V37: 0 | W37: ActionClosed | X37: N
D38: CLOSED | F38: 27.11 cost agreed, step 4 to be issued | G38: 1 | S38: - | T38: 153 | U38: 0 | V38: 0 | W38: ActionClosed | X38: N
D39: CLOSED | F39: 27.11 cost agreed, step 4 to be issued | G39: 3 | S39: - | T39: 154 | U39: 0 | V39: 0 | W39: ActionClosed | X39: N
D40: CLOSED | F40: 27.11, cost agreed SHP to issue step 4 | G40: TOP | S40: - | T40: 155 | U40: 0 | V40: 0 | W40: ActionClosed | X40: N
...

Sheet OWNER LIST
A1: Owner Name | B1: Email | C1: Owner ORG | D1: Role | E1: Main ORG | F1: No sharepoint | G1: NameforMondayemail | H1: ACRONYM
A2: Abigail Abraham | B2: donatella.rocca@un.org | C2: MSTEP | D2: TBC | E2: SOMBP | F2: abigail@mstep.co.uk | G2: Abigail
A3: Alan McBryan | B3: alan.mcbryan@aecom.com | C3: AECOM | D3: MEP Manager | E3: SOMBP | G3: Alan
A4: Alastair Wolstenholme | B4: a.wolstenholme@gardiner.com | C4: G&T | D4: Senior Associate - Cost Management and Contract Administration | E4: G&T | G4: Alastair
A5: Alberto Mastrangelo | B5: pme_to.srl@libero.it | C5: PME | D5: TBC | E5: RPN | G5: Alberto
A6: Alex Graham | B6: alexander.graham1@un.org | C6: SHP | D6: Cost Management | E6: SHP | G6: Alex
A7: Alexandre ROUVELET | B7: alexandre.rouvelet@projection-nouvelle.com | D7: Overall System Engineer | G7: Alexandre
A8: Alessandro Manfredi
A9: Alistair Wade | B9: a.wade@gardiner.com | C9: G&T | D9: Cost Management | E9: G&T | G9: Alistair
A10: Amos Anderini | B10: amos.anderini@rpn-sa.ch | C10: RPN | D10: Deputy HSE & Security Manager | E10: RPN | G10: Amos
A11: Andrea Falchi | B11: andrea.falchi@c2be.uno | C11: C2BE | D11: TBC | E11: C2BE | G11: Andrea
A12: Andrea Hoffman | B12: ahoffmann@hoffmannart.ch | C12: SHP | D12: Heritage/Art Expert | E12: SHP | G12: Andrea
A13: Andrea Sigona | B13: bob.wyse@som.com | C13: SOMBP | D13: Senior Architect | E13: SOMBP | G13: Bob
A14: Andrea VANOSSI | B14: a.vanossi@gmail.com | D14: BIM Manager | G14: Andrea
A15: Andrei Misaila | B15: septimiu.misaila@un.org | C15: UN | D15: TBC | E15: UN | G15: Andrei
A16: Barry Poling | B16: barry.poling@aspenglobal.co.uk | C16: ASPEN | D16: Lean Consultant | E16: ASPEN | G16: Barry
A17: Ben Lang | B17: blang@smwllc.com | C17: SMW | D17: TBC | E17: SOMBP | G17: Ben
A18: Benoit Renault | B18: benoit.renault@un.org | C18: SHP | D18: Senior Electrical Engineer | E18: SHP | G18: Benoit
A19: Bernard Mégevand | B19: bernard.megevand@sbis.ch | C19: SBIS | D19: TBC | E19: SOMBP | G19: Bernard
A20: Bhav | B20: bhav@mstep.co.uk | C20: MSTEP | D20: TBC | E20: SOMBP | G20: Bhav
A21: Billy Clayton | B21: b.clayton@Gardiner.com | C21: G&T | D21: Cost Management | E21: G&T | G21: Billy
A22: Blaise BOURGEOIS | B22: bb@oxalis-landscape.ch | D22: Associate Director | G22: Blaise
A23: Bob Wyse | B23: bob.wyse@som.com | C23: SOMBP | D23: Architect | E23: SOMBP | G23: Bob
A24: Calum Redfern | B24: c.redfern@gardiner.com | C24: G&T | D24: Cost Management | E24: G&T | G24: Calum
A25: Catherine Isabella | B25: catherine.isabella@burckhardt.swiss | C25: SOMBP | D25: Architect | E25: SOMBP | G25: Catherine
A26: Cedric Erard | B26: ce@erard.biz | C26: SOMBP | D26: MEP Manager | E26: SOMBP | G26: Cedric
A27: Cedric Kusendova | B27: cedric.kusendova@un.org | C27: SHP | D27: MEP Manager | E27: SHP | G27: Cedric
A28: Charles de Crisenoy | B28: didier.dequatre@un.org | C28: SHP | D28: Quality Manager | E28: SHP | G28: Didier
A29: Chiara Re Depaolini | B29: chiara.redepaolini@rpn-sa.ch | C29: RPN | D29: Arch Design Specialist | E29: RPN | G29: Chiara
A30: Chris Welch | B30: c.welch@gardiner.com | C30: G&T | D30: Cost Management | E30: G&T | G30: Chris
A31: Christian Bona | B31: christian.bona@rpn-sa.ch | C31: RPN | D31: MEP Manager | E31: RPN | G31: Christian
A32: Cinzia Porracin | B32: porracin@un.org | C32: SHP | D32: Security Site Construction Management | E32: SHP | G32: Cinzia
